Workbook

Sheet لوحة التحكم
A1: منظومة إدارة العقود — شركة البريقة لتسويق النفط
A2: تاريخ اليوم: | B2: =TODAY() -> 46308
A4: إجمالي العقود المسجلة | B4: =COUNTA(العقود!$B$2:$B$501) -> 51
A5: العقود السارية حاليًا | B5: =COUNTIFS(العقود!$R$2:$R$501,"ساري")+COUNTIFS(العقود!$R$2:$R$501,"قريب الانتهاء") -> 37
A6: العقود المنتهية | B6: =COUNTIF(العقود!$R$2:$R$501,"منتهٍ") -> 12
A7: تنتهي خلال 30 يومًا | B7: =COUNTIFS(العقود!$R$2:$R$501,"ساري",العقود!$S$2:$S$501,"<=30")+COUNTIFS(العقود!$R$2:$R$501,"قريب الانتهاء",العقود!$S$2:$S$501,"<=30") -> 0
A8: تنتهي خلال 60 يومًا | B8: =COUNTIFS(العقود!$R$2:$R$501,"ساري",العقود!$S$2:$S$501,"<=60")+COUNTIFS(العقود!$R$2:$R$501,"قريب الانتهاء",العقود!$S$2:$S$501,"<=60") -> 0
A9: تنتهي خلال 90 يومًا | B9: =COUNTIFS(العقود!$R$2:$R$501,"ساري",العقود!$S$2:$S$501,"<=90")+COUNTIFS(العقود!$R$2:$R$501,"قريب الانتهاء",العقود!$S$2:$S$501,"<=90") -> 0
A10: لم يبدأ سريانها بعد | B10: =COUNTIF(العقود!$R$2:$R$501,"لم يبدأ بعد") -> 1
A11: معلقة | B11: =COUNTIF(العقود!$R$2:$R$501,"معلق") -> 1
A12: منتهية قبل موعدها | B12: =COUNTIF(العقود!$R$2:$R$501,"منتهٍ قبل موعده") -> 0
A14: حسب نوع العقد | B14: العدد | D14: حسب الإدارة | E14: العدد | G14: حسب الشركة | H14: العدد
A15: =IF('القوائم والإعدادات'!$A2="","",'القوائم والإعدادات'!$A2) -> بيع وقود الديزل | B15: =IF('القوائم والإعدادات'!$A2="","",COUNTIF(العقود!$E$2:$E$501,'القوائم والإعدادات'!$A2)) -> 33 | D15: =IF('القوائم والإعدادات'!$B2="","",'القوائم والإعدادات'!$B2) -> الإدارة التجارية | E15: =IF('القوائم والإعدادات'!$B2="","",COUNTIF(العقود!$O$2:$O$501,'القوائم والإعدادات'!$B2)) -> 0 | G15: =IF(الشركات!$A2="","",الشركات!$A2) -> شركة الأفق للخدمات النفطية | H15: =IF(الشركات!$A2="","",COUNTIF(العقود!$D$2:$D$501,الشركات!$A2)) -> 0
A16: =IF('القوائم والإعدادات'!$A3="","",'القوائم والإعدادات'!$A3) -> بيع البنزين | B16: =IF('القوائم والإعدادات'!$A3="","",COUNTIF(العقود!$E$2:$E$501,'القوائم والإعدادات'!$A3)) -> 0 | D16: =IF('القوائم والإعدادات'!$B3="","",'القوائم والإعدادات'!$B3) -> إدارة المبيعات | E16: =IF('القوائم والإعدادات'!$B3="","",COUNTIF(العقود!$O$2:$O$501,'القوائم والإعدادات'!$B3)) -> 25 | G16: =IF(الشركات!$A3="","",الشركات!$A3) -> شركة النور للنقل والتشغيل | H16: =IF(الشركات!$A3="","",COUNTIF(العقود!$D$2:$D$501,الشركات!$A3)) -> 0
A17: =IF('القوائم والإعدادات'!$A4="","",'القوائم والإعدادات'!$A4) -> توريد منتجات نفطية | B17: =IF('القوائم والإعدادات'!$A4="","",COUNTIF(العقود!$E$2:$E$501,'القوائم والإعدادات'!$A4)) -> 0 | D17: =IF('القوائم والإعدادات'!$B4="","",'القوائم والإعدادات'!$B4) -> الإدارة الفنية | E17: =IF('القوائم والإعدادات'!$B4="","",COUNTIF(العقود!$O$2:$O$501,'القوائم والإعدادات'!$B4)) -> 0 | G17: =IF(الشركات!$A4="","",الشركات!$A4) -> شركة المدار للتوريدات | H17: =IF(الشركات!$A4="","",COUNTIF(العقود!$D$2:$D$501,الشركات!$A4)) -> 0
A18: =IF('القوائم والإعدادات'!$A5="","",'القوائم والإعدادات'!$A5) -> تقديم خدمات | B18: =IF('القوائم والإعدادات'!$A5="","",COUNTIF(العقود!$E$2:$E$501,'القوائم والإعدادات'!$A5)) -> 0 | D18: =IF('القوائم والإعدادات'!$B5="","",'القوائم والإعدادات'!$B5) -> الشؤون القانونية | E18: =IF('القوائم والإعدادات'!$B5="","",COUNTIF(العقود!$O$2:$O$501,'القوائم والإعدادات'!$B5)) -> 0 | G18: =IF(الشركات!$A5="","",الشركات!$A5) -> شركة الساحل للصيانة | H18: =IF(الشركات!$A5="","",COUNTIF(العقود!$D$2:$D$501,الشركات!$A5)) -> 0
A19: =IF('القوائم والإعدادات'!$A6="","",'القوائم والإعدادات'!$A6) -> صيانة | B19: =IF('القوائم والإعدادات'!$A6="","",COUNTIF(العقود!$E$2:$E$501,'القوائم والإعدادات'!$A6)) -> 0 | D19: =IF('القوائم والإعدادات'!$B6="","",'القوائم والإعدادات'!$B6) | E19: =IF('القوائم والإعدادات'!$B6="","",COUNTIF(العقود!$O$2:$O$501,'القوائم والإعدادات'!$B6)) | G19: =IF(الشركات!$A6="","",الشركات!$A6) -> شركة الواحة للتجارة العامة | H19: =IF(الشركات!$A6="","",COUNTIF(العقود!$D$2:$D$501,الشركات!$A6)) -> 0
A20: =IF('القوائم والإعدادات'!$A7="","",'القوائم والإعدادات'!$A7) -> نقل وتشغيل | B20: =IF('القوائم والإعدادات'!$A7="","",COUNTIF(العقود!$E$2:$E$501,'القوائم والإعدادات'!$A7)) -> 0 | D20: =IF('القوائم والإعدادات'!$B7="","",'القوائم والإعدادات'!$B7) | E20: =IF('القوائم والإعدادات'!$B7="","",COUNTIF(العقود!$O$2:$O$501,'القوائم والإعدادات'!$B7)) | G20: =IF(الشركات!$A7="","",الشركات!$A7) -> شركة الريادة للطاقة | H20: =IF(الشركات!$A7="","",COUNTIF(العقود!$D$2:$D$501,الشركات!$A7)) -> 0
A21: =IF('القوائم والإعدادات'!$A8="","",'القوائم والإعدادات'!$A8) | B21: =IF('القوائم والإعدادات'!$A8="","",COUNTIF(العقود!$E$2:$E$501,'القوائم والإعدادات'!$A8)) | D21: =IF('القوائم والإعدادات'!$B8="","",'القوائم والإعدادات'!$B8) | E21: =IF('القوائم والإعدادات'!$B8="","",COUNTIF(العقود!$O$2:$O$501,'القوائم والإعدادات'!$B8)) | G21: =IF(الشركات!$A8="","",الشركات!$A8) | H21: =IF(الشركات!$A8="","",COUNTIF(العقود!$D$2:$D$501,الشركات!$A8))
A22: =IF('القوائم والإعدادات'!$A9="","",'القوائم والإعدادات'!$A9) | B22: =IF('القوائم والإعدادات'!$A9="","",COUNTIF(العقود!$E$2:$E$501,'القوائم والإعدادات'!$A9)) | D22: =IF('القوائم والإعدادات'!$B9="","",'القوائم والإعدادات'!$B9) | E22: =IF('القوائم والإعدادات'!$B9="","",COUNTIF(العقود!$O$2:$O$501,'القوائم والإعدادات'!$B9)) | G22: =IF(الشركات!$A9="","",الشركات!$A9) | H22: =IF(الشركات!$A9="","",COUNTIF(العقود!$D$2:$D$501,الشركات!$A9))
A23: =IF('القوائم والإعدادات'!$A10="","",'القوائم والإعدادات'!$A10) | B23: =IF('القوائم والإعدادات'!$A10="","",COUNTIF(العقود!$E$2:$E$501,'القوائم والإعدادات'!$A10)) | D23: =IF('القوائم والإعدادات'!$B10="","",'القوائم والإعدادات'!$B10) | E23: =IF('القوائم والإعدادات'!$B10="","",COUNTIF(العقود!$O$2:$O$501,'القوائم والإعدادات'!$B10)) | G23: =IF(الشركات!$A10="","",الشركات!$A10) | H23: =IF(الشركات!$A10="","",COUNTIF(العقود!$D$2:$D$501,الشركات!$A10))
A24: =IF('القوائم والإعدادات'!$A11="","",'القوائم والإعدادات'!$A11) | B24: =IF('القوائم والإعدادات'!$A11="","",COUNTIF(العقود!$E$2:$E$501,'القوائم والإعدادات'!$A11)) | D24: =IF('القوائم والإعدادات'!$B11="","",'القوائم والإعدادات'!$B11) | E24: =IF('القوائم والإعدادات'!$B11="","",COUNTIF(العقود!$O$2:$O$501,'القوائم والإعدادات'!$B11)) | G24: =IF(الشركات!$A11="","",الشركات!$A11) | H24: =IF(الشركات!$A11="","",COUNTIF(العقود!$D$2:$D$501,الشركات!$A11))
A25: =IF('القوائم والإعدادات'!$A12="","",'القوائم والإعدادات'!$A12) | B25: =IF('القوائم والإعدادات'!$A12="","",COUNTIF(العقود!$E$2:$E$501,'القوائم والإعدادات'!$A12)) | D25: =IF('القوائم والإعدادات'!$B12="","",'القوائم والإعدادات'!$B12) | E25: =IF('القوائم والإعدادات'!$B12="","",COUNTIF(العقود!$O$2:$O$501,'القوائم والإعدادات'!$B12)) | G25: =IF(الشركات!$A12="","",الشركات!$A12) | H25: =IF(الشركات!$A12="","",COUNTIF(العقود!$D$2:$D$501,الشركات!$A12))
A26: =IF('القوائم والإعدادات'!$A13="","",'القوائم والإعدادات'!$A13) | B26: =IF('القوائم والإعدادات'!$A13="","",COUNTIF(العقود!$E$2:$E$501,'القوائم والإعدادات'!$A13)) | D26: =IF('القوائم والإعدادات'!$B13="","",'القوائم والإعدادات'!$B13) | E26: =IF('القوائم والإعدادات'!$B13="","",COUNTIF(العقود!$O$2:$O$501,'القوائم والإعدادات'!$B13)) | G26: =IF(الشركات!$A13="","",الشركات!$A13) | H26: =IF(الشركات!$A13="","",COUNTIF(العقود!$D$2:$D$501,الشركات!$A13))
... A33: =IF('القوائم والإعدادات'!$A20="","",'القوائم والإعدادات'!$A20) | B33: =IF('القوائم والإعدادات'!$A20="","",COUNTIF(العقود!$E$2:$E$501,'القوائم والإعدادات'!$A20)) | D33: =IF('القوائم والإعدادات'!$B20="","",'القوائم والإعدادات'!$B20) | E33: =IF('القوائم والإعدادات'!$B20="","",COUNTIF(العقود!$O$2:$O$501,'القوائم والإعدادات'!$B20)) | G33: =IF(الشركات!$A20="","",الشركات!$A20) | H33: =IF(الشركات!$A20="","",COUNTIF(العقود!$D$2:$D$501,الشركات!$A20))
A35: الأرقام تتحدث تلقائيًا عند إضافة أو تعديل العقود في ورقة «العقود».

Sheet العقود
A1: م | B1: رقم العقد | C1: الموقع | D1: الشركة المتعاقدة | E1: نوع العقد | F1: موضوع العقد | G1: تاريخ التوقيع | H1: بداية السريان | I1: الانتهاء الأصلي | J1: الانتهاء الفعلي (بعد التمديد) | K1: المدة الأصلية (شهر) | L1: القيمة | M1: العملة | N1: الكميات | O1: الإدارة المختصة | P1: مسؤول المتابعة | Q1: حالة خاصة | R1: الحالة | S1: المتبقي (يوم) | T1: التنبيه | U1: عدد التمديدات | V1: مسار ملف PDF | W1: ملاحظات وإجراءات | X1: تكرار؟
A2: 1 | B2: ع.ت.د/609 | C2: مصراته / الغيران | D2: شركة الطيور اللامعة لتربية الدواجن | E2: بيع وقود الديزل | F2: تزويد بمنتج الديزل | G2: 46245 | H2: 46250 | I2: 46614 | J2: =IF(B2="","",MAX(I2,_xlfn.MAXIFS(التمديدات!$C$2:$C$301,التمديدات!$A$2:$A$301,B2))) -> 46614 | K2: =IF(OR(H2="",I2=""),"",ROUND((I2-H2)/30.4,0)) -> 12 | L2: 100000 | M2: دينار ليبي | N2: 96468 لتر | O2: إدارة المبيعات | P2: مسؤول 1 | R2: =IF(B2="","",IF(Q2<>"",Q2,IF(H2>TODAY(),"لم يبدأ بعد",IF(J2<TODAY(),"منتهٍ",IF(J2-TODAY()<='القوائم والإعدادات'!$E$2,"قريب الانتهاء","ساري"))))) -> ساري | S2: =IF(B2="","",J2-TODAY()) -> 306 | T2: =IF(OR(R2="ساري",R2="قريب الانتهاء"),IF(S2<='القوائم والإعدادات'!$E$4,"عاجل",IF(S2<='القوائم والإعدادات'!$E$3,"خلال 60 يوم",IF(S2<='القوائم والإعدادات'!$E$2,"خلال 90 يوم",""))),"") | U2: =IF(B2="","",COUNTIF(التمديدات!$A$2:$A$301,B2)) -> 0 | X2: =IF(B2="","",IF(COUNTIFS($B$2:$B$501,B2,$D$2:$D$501,D2)>1,"مكرر!",""))
A3: 2 | B3: ع.ت.د/627 | C3: زليتن | D3: شركة الخيرات الاحسن للمقاولات العامة والاستثمار العقاري | E3: بيع وقود الديزل | F3: تزويد بمنتج الديزل | G3: 46246 | H3: 46250 | I3: 46614 | J3: =IF(B3="","",MAX(I3,_xlfn.MAXIFS(التمديدات!$C$2:$C$301,التمديدات!$A$2:$A$301,B3))) -> 46614 | K3: =IF(OR(H3="",I3=""),"",ROUND((I3-H3)/30.4,0)) -> 12 | L3: 200000 | M3: دينار ليبي | N3: 56640 لتر | O3: إدارة المبيعات | P3: مسؤول 2 | R3: =IF(B3="","",IF(Q3<>"",Q3,IF(H3>TODAY(),"لم يبدأ بعد",IF(J3<TODAY(),"منتهٍ",IF(J3-TODAY()<='القوائم والإعدادات'!$E$2,"قريب الانتهاء","ساري"))))) -> ساري | S3: =IF(B3="","",J3-TODAY()) -> 306 | T3: =IF(OR(R3="ساري",R3="قريب الانتهاء"),IF(S3<='القوائم والإعدادات'!$E$4,"عاجل",IF(S3<='القوائم والإعدادات'!$E$3,"خلال 60 يوم",IF(S3<='القوائم والإعدادات'!$E$2,"خلال 90 يوم",""))),"") | U3: =IF(B3="","",COUNTIF(التمديدات!$A$2:$A$301,B3)) -> 0 | X3: =IF(B3="","",IF(COUNTIFS($B$2:$B$501,B3,$D$2:$D$501,D3)>1,"مكرر!",""))
A4: 3 | B4: ع.ت.د/621 | C4: قصر الخيار | D4: شركة سد أبو عباد لصناعة الزلط | E4: بيع وقود الديزل | F4: تزويد بمنتج الديزل | G4: 46239 | H4: 46250 | I4: 46614 | J4: =IF(B4="","",MAX(I4,_xlfn.MAXIFS(التمديدات!$C$2:$C$301,التمديدات!$A$2:$A$301,B4))) -> 46614 | K4: =IF(OR(H4="",I4=""),"",ROUND((I4-H4)/30.4,0)) -> 12 | L4: 300000 | M4: دينار ليبي | N4: 47600 لتر | O4: إدارة المبيعات | P4: مسؤول 3 | R4: =IF(B4="","",IF(Q4<>"",Q4,IF(H4>TODAY(),"لم يبدأ بعد",IF(J4<TODAY(),"منتهٍ",IF(J4-TODAY()<='القوائم والإعدادات'!$E$2,"قريب الانتهاء","ساري"))))) -> ساري | S4: =IF(B4="","",J4-TODAY()) -> 306 | T4: =IF(OR(R4="ساري",R4="قريب الانتهاء"),IF(S4<='القوائم والإعدادات'!$E$4,"عاجل",IF(S4<='القوائم والإعدادات'!$E$3,"خلال 60 يوم",IF(S4<='القوائم والإعدادات'!$E$2,"خلال 90 يوم",""))),"") | U4: =IF(B4="","",COUNTIF(التمديدات!$A$2:$A$301,B4)) -> 0 | X4: =IF(B4="","",IF(COUNTIFS($B$2:$B$501,B4,$D$2:$D$501,D4)>1,"مكرر!",""))
A5: 4 | B5: ع.ت.د /611 | C5: مصراته / السكت | D5: شركة الضيافة الليبية لصناعة المواد الغذائية والمشروبات | E5: بيع وقود الديزل | F5: تزويد بمنتج الديزل | G5: 46245 | H5: 46250 | I5: 46614 | J5: =IF(B5="","",MAX(I5,_xlfn.MAXIFS(التمديدات!$C$2:$C$301,التمديدات!$A$2:$A$301,B5))) -> 46614 | K5: =IF(OR(H5="",I5=""),"",ROUND((I5-H5)/30.4,0)) -> 12 | L5: 400000 | M5: دينار ليبي | N5: 89800 لتر | O5: إدارة المبيعات | P5: مسؤول 4 | R5: =IF(B5="","",IF(Q5<>"",Q5,IF(H5>TODAY(),"لم يبدأ بعد",IF(J5<TODAY(),"منتهٍ",IF(J5-TODAY()<='القوائم والإعدادات'!$E$2,"قريب الانتهاء","ساري"))))) -> ساري | S5: =IF(B5="","",J5-TODAY()) -> 306 | T5: =IF(OR(R5="ساري",R5="قريب الانتهاء"),IF(S5<='القوائم والإعدادات'!$E$4,"عاجل",IF(S5<='القوائم والإعدادات'!$E$3,"خلال 60 يوم",IF(S5<='القوائم والإعدادات'!$E$2,"خلال 90 يوم",""))),"") | U5: =IF(B5="","",COUNTIF(التمديدات!$A$2:$A$301,B5)) -> 0 | X5: =IF(B5="","",IF(COUNTIFS($B$2:$B$501,B5,$D$2:$D$501,D5)>1,"مكرر!",""))
A6: 5 | B6: ع.ت.د /629 | C6: مصراته | D6: شركة الامل لتجميع وإعادة المخلفات الصناعية | E6: بيع منتج الزيت الثقيل | F6: تزويد بمنتج الزيت الثقيل | G6: 46245 | H6: 46250 | I6: 46614 | J6: =IF(B6="","",MAX(I6,_xlfn.MAXIFS(التمديدات!$C$2:$C$301,التمديدات!$A$2:$A$301,B6))) -> 46614 | K6: =IF(OR(H6="",I6=""),"",ROUND((I6-H6)/30.4,0)) -> 12 | L6: 500000 | M6: دينار ليبي | N6: 200 طن | O6: إدارة المبيعات | P6: مسؤول 5 | R6: =IF(B6="","",IF(Q6<>"",Q6,IF(H6>TODAY(),"لم يبدأ بعد",IF(J6<TODAY(),"منتهٍ",IF(J6-TODAY()<='القوائم والإعدادات'!$E$2,"قريب الانتهاء","ساري"))))) -> ساري | S6: =IF(B6="","",J6-TODAY()) -> 306 | T6: =IF(OR(R6="ساري",R6="قريب الانتهاء"),IF(S6<='القوائم والإعدادات'!$E$4,"عاجل",IF(S6<='القوائم والإعدادات'!$E$3,"خلال 60 يوم",IF(S6<='القوائم والإعدادات'!$E$2,"خلال 90 يوم",""))),"") | U6: =IF(B6="","",COUNTIF(التمديدات!$A$2:$A$301,B6)) -> 0 | X6: =IF(B6="","",IF(COUNTIFS($B$2:$B$501,B6,$D$2:$D$501,D6)>1,"مكرر!",""))
A7: 6 | B7: ع.ت.د /612 | C7: السوكنة / الجفرة | D7: شركة زمام لتربية الدواجن | E7: بيع وقود الديزل | F7: تزويد بمنتج الديزل | G7: 46245 | H7: 46250 | I7: 46614 | J7: =IF(B7="","",MAX(I7,_xlfn.MAXIFS(التمديدات!$C$2:$C$301,التمديدات!$A$2:$A$301,B7))) -> 46614 | K7: =IF(OR(H7="",I7=""),"",ROUND((I7-H7)/30.4,0)) -> 12 | L7: 600000 | M7: دينار ليبي | N7: 46800 لتر | O7: إدارة المبيعات | P7: مسؤول 6 | R7: =IF(B7="","",IF(Q7<>"",Q7,IF(H7>TODAY(),"لم يبدأ بعد",IF(J7<TODAY(),"منتهٍ",IF(J7-TODAY()<='القوائم والإعدادات'!$E$2,"قريب الانتهاء","ساري"))))) -> ساري | S7: =IF(B7="","",J7-TODAY()) -> 306 | T7: =IF(OR(R7="ساري",R7="قريب الانتهاء"),IF(S7<='القوائم والإعدادات'!$E$4,"عاجل",IF(S7<='القوائم والإعدادات'!$E$3,"خلال 60 يوم",IF(S7<='القوائم والإعدادات'!$E$2,"خلال 90 يوم",""))),"") | U7: =IF(B7="","",COUNTIF(التمديدات!$A$2:$A$301,B7)) -> 0 | X7: =IF(B7="","",IF(COUNTIFS($B$2:$B$501,B7,$D$2:$D$501,D7)>1,"مكرر!",""))
A8: 7 | B8: ع.ت.د /610 | C8: يفرن | D8: إدارة الخدمات النظافة العامة يفرن | E8: بيع وقود الديزل | F8: تزويد بمنتج الديزل | G8: 45878 | H8: 46250 | I8: 46614 | J8: =IF(B8="","",MAX(I8,_xlfn.MAXIFS(التمديدات!$C$2:$C$301,التمديدات!$A$2:$A$301,B8))) -> 46614 | K8: =IF(OR(H8="",I8=""),"",ROUND((I8-H8)/30.4,0)) -> 12 | L8: 700000 | M8: دينار ليبي | N8: 8700 لتر | O8: إدارة المبيعات | P8: مسؤول 7 | R8: =IF(B8="","",IF(Q8<>"",Q8,IF(H8>TODAY(),"لم يبدأ بعد",IF(J8<TODAY(),"منتهٍ",IF(J8-TODAY()<='القوائم والإعدادات'!$E$2,"قريب الانتهاء","ساري"))))) -> ساري | S8: =IF(B8="","",J8-TODAY()) -> 306 | T8: =IF(OR(R8="ساري",R8="قريب الانتهاء"),IF(S8<='القوائم والإعدادات'!$E$4,"عاجل",IF(S8<='القوائم والإعدادات'!$E$3,"خلال 60 يوم",IF(S8<='القوائم والإعدادات'!$E$2,"خلال 90 يوم",""))),"") | U8: =IF(B8="","",COUNTIF(التمديدات!$A$2:$A$301,B8)) -> 0 | X8: =IF(B8="","",IF(COUNTIFS($B$2:$B$501,B8,$D$2:$D$501,D8)>1,"مكرر!",""))
A9: 8 | B9: ع.ت.د /644 | C9: مصراته /راس الطوبة | D9: شركة قرارة لصناعة الرخام و القرنيت | E9: بيع وقود الديزل | F9: تزويد بمنتج الديزل | G9: 46246 | H9: 46250 | I9: 46614 | J9: =IF(B9="","",MAX(I9,_xlfn.MAXIFS(التمديدات!$C$2:$C$301,التمديدات!$A$2:$A$301,B9))) -> 46614 | K9: =IF(OR(H9="",I9=""),"",ROUND((I9-H9)/30.4,0)) -> 12 | L9: 800000 | M9: دينار ليبي | N9: 68960 لتر | O9: إدارة المبيعات | P9: مسؤول 8 | R9: =IF(B9="","",IF(Q9<>"",Q9,IF(H9>TODAY(),"لم يبدأ بعد",IF(J9<TODAY(),"منتهٍ",IF(J9-TODAY()<='القوائم والإعدادات'!$E$2,"قريب الانتهاء","ساري"))))) -> ساري | S9: =IF(B9="","",J9-TODAY()) -> 306 | T9: =IF(OR(R9="ساري",R9="قريب الانتهاء"),IF(S9<='القوائم والإعدادات'!$E$4,"عاجل",IF(S9<='القوائم والإعدادات'!$E$3,"خلال 60 يوم",IF(S9<='القوائم والإعدادات'!$E$2,"خلال 90 يوم",""))),"") | U9: =IF(B9="","",COUNTIF(التمديدات!$A$2:$A$301,B9)) -> 0 | X9: =IF(B9="","",IF(COUNTIFS($B$2:$B$501,B9,$D$2:$D$501,D9)>1,"مكرر!",""))
A10: 9 | B10: ع.ت.د / 667 | C10: الخمس | D10: شركة الشروق الليبية للمطاحن و الاعلاف | E10: بيع وقود الديزل | F10: تزويد بمنتج الديزل | G10: 46260 | H10: 46264 | I10: 46628 | J10: =IF(B10="","",MAX(I10,_xlfn.MAXIFS(التمديدات!$C$2:$C$301,التمديدات!$A$2:$A$301,B10))) -> 46628 | K10: =IF(OR(H10="",I10=""),"",ROUND((I10-H10)/30.4,0)) -> 12 | L10: 900000 | M10: دينار ليبي | N10: 97300 لتر | O10: إدارة المبيعات | P10: مسؤول 9 | R10: =IF(B10="","",IF(Q10<>"",Q10,IF(H10>TODAY(),"لم يبدأ بعد",IF(J10<TODAY(),"منتهٍ",IF(J10-TODAY()<='القوائم والإعدادات'!$E$2,"قريب الانتهاء","ساري"))))) -> ساري | S10: =IF(B10="","",J10-TODAY()) -> 320 | T10: =IF(OR(R10="ساري",R10="قريب الانتهاء"),IF(S10<='القوائم والإعدادات'!$E$4,"عاجل",IF(S10<='القوائم والإعدادات'!$E$3,"خلال 60 يوم",IF(S10<='القوائم والإعدادات'!$E$2,"خلال 90 يوم",""))),"") | U10: =IF(B10="","",COUNTIF(التمديدات!$A$2:$A$301,B10)) -> 0 | X10: =IF(B10="","",IF(COUNTIFS($B$2:$B$501,B10,$D$2:$D$501,D10)>1,"مكرر!",""))
A11: 10 | B11: ع.ت.د /654 | C11: مصراته | D11: شركة الوسيطة لصناعة المبيدات الحشرية | E11: بيع منتج غاز مسال | F11: بيع منتج غاز مسال | G11: 46253 | H11: 46254 | I11: 46618 | J11: =IF(B11="","",MAX(I11,_xlfn.MAXIFS(التمديدات!$C$2:$C$301,التمديدات!$A$2:$A$301,B11))) -> 46618 | K11: =IF(OR(H11="",I11=""),"",ROUND((I11-H11)/30.4,0)) -> 12 | L11: 1000000 | M11: دينار ليبي | N11: 60 ألف طن | O11: إدارة المبيعات | P11: مسؤول 10 | Q11: معلق | R11: =IF(B11="","",IF(Q11<>"",Q11,IF(H11>TODAY(),"لم يبدأ بعد",IF(J11<TODAY(),"منتهٍ",IF(J11-TODAY()<='القوائم والإعدادات'!$E$2,"قريب الانتهاء","ساري"))))) -> معلق | S11: =IF(B11="","",J11-TODAY()) -> 310 | T11: =IF(OR(R11="ساري",R11="قريب الانتهاء"),IF(S11<='القوائم والإعدادات'!$E$4,"عاجل",IF(S11<='القوائم والإعدادات'!$E$3,"خلال 60 يوم",IF(S11<='القوائم والإعدادات'!$E$2,"خلال 90 يوم",""))),"") | U11: =IF(B11="","",COUNTIF(التمديدات!$A$2:$A$301,B11)) -> 0 | X11: =IF(B11="","",IF(COUNTIFS($B$2:$B$501,B11,$D$2:$D$501,D11)>1,"مكرر!",""))
A12: 11 | B12: ع.ت.د /613 | C12: مصراته / تاورغاء | D12: مصنع الفتح لصناعة الزلط | E12: بيع وقود الديزل | F12: تزويد بمنتج الديزل | G12: 46244 | H12: 46250 | I12: 46614 | J12: =IF(B12="","",MAX(I12,_xlfn.MAXIFS(التمديدات!$C$2:$C$301,التمديدات!$A$2:$A$301,B12))) -> 46614 | K12: =IF(OR(H12="",I12=""),"",ROUND((I12-H12)/30.4,0)) -> 12 | N12: 43720لتر | O12: إدارة المبيعات | R12: =IF(B12="","",IF(Q12<>"",Q12,IF(H12>TODAY(),"لم يبدأ بعد",IF(J12<TODAY(),"منتهٍ",IF(J12-TODAY()<='القوائم والإعدادات'!$E$2,"قريب الانتهاء","ساري"))))) -> ساري | S12: =IF(B12="","",J12-TODAY()) -> 306 | T12: =IF(OR(R12="ساري",R12="قريب الانتهاء"),IF(S12<='القوائم والإعدادات'!$E$4,"عاجل",IF(S12<='القوائم والإعدادات'!$E$3,"خلال 60 يوم",IF(S12<='القوائم والإعدادات'!$E$2,"خلال 90 يوم",""))),"") | U12: =IF(B12="","",COUNTIF(التمديدات!$A$2:$A$301,B12)) -> 0 | X12: =IF(B12="","",IF(COUNTIFS($B$2:$B$501,B12,$D$2:$D$501,D12)>1,"مكرر!",""))
A13: 12 | B13: ع.ت.د /614 | C13: طرابلس | D13: شركة الجيد للإستيراد المواد الغذائية | E13: بيع وقود الديزل | F13: تزويد بمنتج الديزل | G13: 46245 | H13: 46250 | I13: 46614 | J13: =IF(B13="","",MAX(I13,_xlfn.MAXIFS(التمديدات!$C$2:$C$301,التمديدات!$A$2:$A$301,B13))) -> 46614 | K13: =IF(OR(H13="",I13=""),"",ROUND((I13-H13)/30.4,0)) -> 12 | N13: 26660لتر | O13: إدارة المبيعات | R13: =IF(B13="","",IF(Q13<>"",Q13,IF(H13>TODAY(),"لم يبدأ بعد",IF(J13<TODAY(),"منتهٍ",IF(J13-TODAY()<='القوائم والإعدادات'!$E$2,"قريب الانتهاء","ساري"))))) -> ساري | S13: =IF(B13="","",J13-TODAY()) -> 306 | T13: =IF(OR(R13="ساري",R13="قريب الانتهاء"),IF(S13<='القوائم والإعدادات'!$E$4,"عاجل",IF(S13<='القوائم والإعدادات'!$E$3,"خلال 60 يوم",IF(S13<='القوائم والإعدادات'!$E$2,"خلال 90 يوم",""))),"") | U13: =IF(B13="","",COUNTIF(التمديدات!$A$2:$A$301,B13)) -> 0 | W13: تزويد من منطقة مصراته بكمية 47900 لتر محددة من اللجنة الفرعية مصراته | X13: =IF(B13="","",IF(COUNTIFS($B$2:$B$501,B13,$D$2:$D$501,D13)>1,"مكرر!",""))
A14: 13 | B14: ع.ت.د /619 | C14: صبراته | D14: شركة صرمان الحديثة لصناعة مواد البناء و السيراميك | E14: بيع وقود الديزل | F14: تزويد بمنتج الديزل | G14: 46243 | H14: 46250 | I14: 46614 | J14: =IF(B14="","",MAX(I14,_xlfn.MAXIFS(التمديدات!$C$2:$C$301,التمديدات!$A$2:$A$301,B14))) -> 46614 | K14: =IF(OR(H14="",I14=""),"",ROUND((I14-H14)/30.4,0)) -> 12 | N14: 80000لتر | O14: إدارة المبيعات | R14: =IF(B14="","",IF(Q14<>"",Q14,IF(H14>TODAY(),"لم يبدأ بعد",IF(J14<TODAY(),"منتهٍ",IF(J14-TODAY()<='القوائم والإعدادات'!$E$2,"قريب الانتهاء","ساري"))))) -> ساري | S14: =IF(B14="","",J14-TODAY()) -> 306 | T14: =IF(OR(R14="ساري",R14="قريب الانتهاء"),IF(S14<='القوائم والإعدادات'!$E$4,"عاجل",IF(S14<='القوائم والإعدادات'!$E$3,"خلال 60 يوم",IF(S14<='القوائم والإعدادات'!$E$2,"خلال 90 يوم",""))),"") | U14: =IF(B14="","",COUNTIF(التمديدات!$A$2:$A$301,B14)) -> 0 | X14: =IF(B14="","",IF(COUNTIFS($B$2:$B$501,B14,$D$2:$D$501,D14)>1,"مكرر!",""))
A15: 14 | B15: ع.ت.د /608 | C15: طرابلس | D15: شركة أبراج العرب العالمية للصناعات الخراسنية و مواد البناء | E15: بيع وقود الديزل | F15: تزويد بمنتج الديزل | G15: 46243 | H15: 46247 | I15: 46611 | J15: =IF(B15="","",MAX(I15,_xlfn.MAXIFS(التمديدات!$C$2:$C$301,التمديدات!$A$2:$A$301,B15))) -> 46611 | K15: =IF(OR(H15="",I15=""),"",ROUND((I15-H15)/30.4,0)) -> 12 | N15: 41538لتر | O15: إدارة المبيعات | R15: =IF(B15="","",IF(Q15<>"",Q15,IF(H15>TODAY(),"لم يبدأ بعد",IF(J15<TODAY(),"منتهٍ",IF(J15-TODAY()<='القوائم والإعدادات'!$E$2,"قريب الانتهاء","ساري"))))) -> ساري | S15: =IF(B15="","",J15-TODAY()) -> 303 | T15: =IF(OR(R15="ساري",R15="قريب الانتهاء"),IF(S15<='القوائم والإعدادات'!$E$4,"عاجل",IF(S15<='القوائم والإعدادات'!$E$3,"خلال 60 يوم",IF(S15<='القوائم والإعدادات'!$E$2,"خلال 90 يوم",""))),"") | U15: =IF(B15="","",COUNTIF(التمديدات!$A$2:$A$301,B15)) -> 0 | X15: =IF(B15="","",IF(COUNTIFS($B$2:$B$501,B15,$D$2:$D$501,D15)>1,"مكرر!",""))
A16: 15 | B16: ع.ت.د / 607 | C16: باطن الجبل / بدر | D16: شركة الموج الجارف لإنتاج الزلط | E16: بيع وقود الديزل | F16: تزويد بمنتج الديزل | G16: 46244 | H16: 46247 | I16: 46611 | J16: =IF(B16="","",MAX(I16,_xlfn.MAXIFS(التمديدات!$C$2:$C$301,التمديدات!$A$2:$A$301,B16))) -> 46611 | K16: =IF(OR(H16="",I16=""),"",ROUND((I16-H16)/30.4,0)) -> 12 | N16: 60000لتر | O16: إدارة المبيعات | R16: =IF(B16="","",IF(Q16<>"",Q16,IF(H16>TODAY(),"لم يبدأ بعد",IF(J16<TODAY(),"منتهٍ",IF(J16-TODAY()<='القوائم والإعدادات'!$E$2,"قريب الانتهاء","ساري"))))) -> ساري | S16: =IF(B16="","",J16-TODAY()) -> 303 | T16: =IF(OR(R16="ساري",R16="قريب الانتهاء"),IF(S16<='القوائم والإعدادات'!$E$4,"عاجل",IF(S16<='القوائم والإعدادات'!$E$3,"خلال 60 يوم",IF(S16<='القوائم والإعدادات'!$E$2,"خلال 90 يوم",""))),"") | U16: =IF(B16="","",COUNTIF(التمديدات!$A$2:$A$301,B16)) -> 0 | X16: =IF(B16="","",IF(COUNTIFS($B$2:$B$501,B16,$D$2:$D$501,D16)>1,"مكرر!",""))
A17: 16 | B17: ع.ت.د / 622 | C17: الزاوية | D17: شركة القرية المتحدة لصناعة و تعليب المواد الغذائية | E17: بيع منتج الزيت الثقيل | F17: تزويد بمنتج الزيت الثقيل | G17: 46244 | H17: 46250 | I17: 46614 | J17: =IF(B17="","",MAX(I17,_xlfn.MAXIFS(التمديدات!$C$2:$C$301,التمديدات!$A$2:$A$301,B17))) -> 46614 | K17: =IF(OR(H17="",I17=""),"",ROUND((I17-H17)/30.4,0)) -> 12 | N17: 40000لتر | O17: إدارة المبيعات | R17: =IF(B2="","",IF(Q17<>"",Q17,IF(I2>TODAY(),"لم يبدأ بعد",IF(J17<TODAY(),"منتهٍ",IF(J17-TODAY()<='القوائم والإعدادات'!$E$2,"قريب الانتهاء","ساري"))))) -> لم يبدأ بعد | S17: =IF(B2="","",J17-TODAY()) -> 306 | T17: =IF(OR(R17="ساري",R17="قريب الانتهاء"),IF(S17<='القوائم والإعدادات'!$E$4,"عاجل",IF(S17<='القوائم والإعدادات'!$E$3,"خلال 60 يوم",IF(S17<='القوائم والإعدادات'!$E$2,"خلال 90 يوم",""))),"") | U17: =IF(B2="","",COUNTIF(التمديدات!$A$2:$A$301,B2)) -> 0 | X17: =IF(B2="","",IF(COUNTIFS($B$2:$B$501,B2,$D$2:$D$501,D17)>1,"مكرر!",""))
A18: 17 | B18: ع.ت.د /635 | C18: مصراته | D18: شركة الخنفاس لصناعة سحب الاسلاك | E18: بيع منتج غاز مسال | F18: بيع منتج غاز مسال | G18: 46250 | H18: 46252 | I18: 46616 | J18: =IF(B18="","",MAX(I18,_xlfn.MAXIFS(التمديدات!$C$2:$C$301,التمديدات!$A$2:$A$301,B18))) -> 46616 | K18: =IF(OR(H18="",I18=""),"",ROUND((I18-H18)/30.4,0)) -> 12 | N18: 14طن | O18: إدارة المبيعات | R18: =IF(B18="","",IF(Q18<>"",Q18,IF(H18>TODAY(),"لم يبدأ بعد",IF(J18<TODAY(),"منتهٍ",IF(J18-TODAY()<='القوائم والإعدادات'!$E$2,"قريب الانتهاء","ساري"))))) -> ساري | S18: =IF(B18="","",J18-TODAY()) -> 308 | T18: =IF(OR(R18="ساري",R18="قريب الانتهاء"),IF(S18<='القوائم والإعدادات'!$E$4,"عاجل",IF(S18<='القوائم والإعدادات'!$E$3,"خلال 60 يوم",IF(S18<='القوائم والإعدادات'!$E$2,"خلال 90 يوم",""))),"") | U18: =IF(B18="","",COUNTIF(التمديدات!$A$2:$A$301,B18)) -> 0 | X18: =IF(B18="","",IF(COUNTIFS($B$2:$B$501,B18,$D$2:$D$501,D18)>1,"مكرر!",""))
A19: 18 | B19: ع.ت.د /674 | C19: زليتن | D19: شركة الرطيل و شوركاءة لصناعة مواد البناء | E19: بيع وقود الديزل | F19: تزويد بمنتج الديزل | G19: 46260 | H19: 46264 | I19: 46628 | J19: =IF(B19="","",MAX(I19,_xlfn.MAXIFS(التمديدات!$C$2:$C$301,التمديدات!$A$2:$A$301,B19))) -> 46628 | K19: =IF(OR(H19="",I19=""),"",ROUND((I19-H19)/30.4,0)) -> 12 | N19: 105760لتر | O19: إدارة المبيعات | R19: =IF(B19="","",IF(Q19<>"",Q19,IF(H19>TODAY(),"لم يبدأ بعد",IF(J19<TODAY(),"منتهٍ",IF(J19-TODAY()<='القوائم والإعدادات'!$E$2,"قريب الانتهاء","ساري"))))) -> ساري | S19: =IF(B19="","",J19-TODAY()) -> 320 | T19: =IF(OR(R19="ساري",R19="قريب الانتهاء"),IF(S19<='القوائم والإعدادات'!$E$4,"عاجل",IF(S19<='القوائم والإعدادات'!$E$3,"خلال 60 يوم",IF(S19<='القوائم والإعدادات'!$E$2,"خلال 90 يوم",""))),"") | U19: =IF(B19="","",COUNTIF(التمديدات!$A$2:$A$301,B19)) -> 0 | X19: =IF(B19="","",IF(COUNTIFS($B$2:$B$501,B19,$D$2:$D$501,D19)>1,"مكرر!",""))
A20: 19 | B20: ع.ت.د /676 | C20: مصراته | D20: شركة بيتا بوليمر لصناعات الكيماوية | E20: بيع وقود الديزل | F20: تزويد بمنتج الديزل | G20: 46260 | H20: 46264 | I20: 46628 | J20: =IF(B20="","",MAX(I20,_xlfn.MAXIFS(التمديدات!$C$2:$C$301,التمديدات!$A$2:$A$301,B20))) -> 46628 | K20: =IF(OR(H20="",I20=""),"",ROUND((I20-H20)/30.4,0)) -> 12 | N20: 165240لتر | O20: إدارة المبيعات | R20: =IF(B20="","",IF(Q20<>"",Q20,IF(H20>TODAY(),"لم يبدأ بعد",IF(J20<TODAY(),"منتهٍ",IF(J20-TODAY()<='القوائم والإعدادات'!$E$2,"قريب الانتهاء","ساري"))))) -> ساري | S20: =IF(B20="","",J20-TODAY()) -> 320 | T20: =IF(OR(R20="ساري",R20="قريب الانتهاء"),IF(S20<='القوائم والإعدادات'!$E$4,"عاجل",IF(S20<='القوائم والإعدادات'!$E$3,"خلال 60 يوم",IF(S20<='القوائم والإعدادات'!$E$2,"خلال 90 يوم",""))),"") | U20: =IF(B20="","",COUNTIF(التمديدات!$A$2:$A$301,B20)) -> 0 | X20: =IF(B20="","",IF(COUNTIFS($B$2:$B$501,B20,$D$2:$D$501,D20)>1,"مكرر!",""))
A21: 20 | B21: ع.ت.د /666 | C21: مصراته | D21: شركة السيل بلاست للصناعات البلاستيكية | E21: بيع وقود الديزل | F21: تزويد بمنتج الديزل | G21: 46260 | H21: 46264 | I21: 46628 | J21: =IF(B21="","",MAX(I21,_xlfn.MAXIFS(التمديدات!$C$2:$C$301,التمديدات!$A$2:$A$301,B21))) -> 46628 | K21: =IF(OR(H21="",I21=""),"",ROUND((I21-H21)/30.4,0)) -> 12 | N21: 104320لتر | O21: إدارة المبيعات | R21: =IF(B21="","",IF(Q21<>"",Q21,IF(H21>TODAY(),"لم يبدأ بعد",IF(J21<TODAY(),"منتهٍ",IF(J21-TODAY()<='القوائم والإعدادات'!$E$2,"قريب الانتهاء","ساري"))))) -> ساري | S21: =IF(B21="","",J21-TODAY()) -> 320 | T21: =IF(OR(R21="ساري",R21="قريب الانتهاء"),IF(S21<='القوائم والإعدادات'!$E$4,"عاجل",IF(S21<='القوائم والإعدادات'!$E$3,"خلال 60 يوم",IF(S21<='القوائم والإعدادات'!$E$2,"خلال 90 يوم",""))),"") | U21: =IF(B21="","",COUNTIF(التمديدات!$A$2:$A$301,B21)) -> 0 | X21: =IF(B21="","",IF(COUNTIFS($B$2:$B$501,B21,$D$2:$D$501,D21)>1,"مكرر!",""))
A22: 21 | B22: ع.ت.د / 655 | C22: العجيلات | D22: إدارة الخدمات النظافة العجيلات | E22: بيع وقود الديزل | F22: تزويد بمنتج الديزل | G22: 46254 | H22: 46258 | I22: 46622 | J22: =IF(B22="","",MAX(I22,_xlfn.MAXIFS(التمديدات!$C$2:$C$301,التمديدات!$A$2:$A$301,B22))) -> 46622 | K22: =IF(OR(H22="",I22=""),"",ROUND((I22-H22)/30.4,0)) -> 12 | N22: 15000لتر | O22: إدارة المبيعات | R22: =IF(B22="","",IF(Q22<>"",Q22,IF(H22>TODAY(),"لم يبدأ بعد",IF(J22<TODAY(),"منتهٍ",IF(J22-TODAY()<='القوائم والإعدادات'!$E$2,"قريب الانتهاء","ساري"))))) -> ساري | S22: =IF(B22="","",J22-TODAY()) -> 314 | T22: =IF(OR(R22="ساري",R22="قريب الانتهاء"),IF(S22<='القوائم والإعدادات'!$E$4,"عاجل",IF(S22<='القوائم والإعدادات'!$E$3,"خلال 60 يوم",IF(S22<='القوائم والإعدادات'!$E$2,"خلال 90 يوم",""))),"") | U22: =IF(B22="","",COUNTIF(التمديدات!$A$2:$A$301,B22)) -> 0 | X22: =IF(B22="","",IF(COUNTIFS($B$2:$B$501,B22,$D$2:$D$501,D22)>1,"مكرر!",""))
A23: 22 | B23: ع.ت.د /696 | C23: طرابلس | D23: شركة خيرات الوادي لصناعة المواد الغذائية | E23: بيع وقود الديزل | F23: تزويد بمنتج الديزل | G23: 46266 | H23: 46268 | I23: 46632 | J23: =IF(B23="","",MAX(I23,_xlfn.MAXIFS(التمديدات!$C$2:$C$301,التمديدات!$A$2:$A$301,B23))) -> 46632 | K23: =IF(OR(H23="",I23=""),"",ROUND((I23-H23)/30.4,0)) -> 12 | N23: 58000لتر | O23: إدارة المبيعات | R23: =IF(B23="","",IF(Q23<>"",Q23,IF(H23>TODAY(),"لم يبدأ بعد",IF(J23<TODAY(),"منتهٍ",IF(J23-TODAY()<='القوائم والإعدادات'!$E$2,"قريب الانتهاء","ساري"))))) -> ساري | S23: =IF(B23="","",J23-TODAY()) -> 324 | T23: =IF(OR(R23="ساري",R23="قريب الانتهاء"),IF(S23<='القوائم والإعدادات'!$E$4,"عاجل",IF(S23<='القوائم والإعدادات'!$E$3,"خلال 60 يوم",IF(S23<='القوائم والإعدادات'!$E$2,"خلال 90 يوم",""))),"") | U23: =IF(B23="","",COUNTIF(التمديدات!$A$2:$A$301,B23)) -> 0 | W23: 70000لتر في أوقات الذروة و ذلك حسب تقرير اللجنة الفرعية | X23: =IF(B23="","",IF(COUNTIFS($B$2:$B$501,B23,$D$2:$D$501,D23)>1,"مكرر!",""))
A24: 23 | B24: ع.ت.د /35 | C24: طرابلس /طريق المطار | D24: شركة الصرح الراقي لانتاج الزلط | E24: بيع وقود الديزل | F24: تزويد بمنتج الديزل | G24: 46267 | H24: 46268 | I24: 46632 | J24: =IF(B24="","",MAX(I24,_xlfn.MAXIFS(التمديدات!$C$2:$C$301,التمديدات!$A$2:$A$301,B24))) -> 46632 | K24: =IF(OR(H24="",I24=""),"",ROUND((I24-H24)/30.4,0)) -> 12 | N24: 78560لتر | O24: إدارة المبيعات | R24: =IF(B24="","",IF(Q24<>"",Q24,IF(H24>TODAY(),"لم يبدأ بعد",IF(J24<TODAY(),"منتهٍ",IF(J24-TODAY()<='القوائم والإعدادات'!$E$2,"قريب الانتهاء","ساري"))))) -> ساري | S24: =IF(B24="","",J24-TODAY()) -> 324 | T24: =IF(OR(R24="ساري",R24="قريب الانتهاء"),IF(S24<='القوائم والإعدادات'!$E$4,"عاجل",IF(S24<='القوائم والإعدادات'!$E$3,"خلال 60 يوم",IF(S24<='القوائم والإعدادات'!$E$2,"خلال 90 يوم",""))),"") | U24: =IF(B24="","",COUNTIF(التمديدات!$A$2:$A$301,B24)) -> 0 | X24: =IF(B24="","",IF(COUNTIFS($B$2:$B$501,B24,$D$2:$D$501,D24)>1,"مكرر!",""))
A25: 24 | B25: ع.ت.د /675 | C25: سبها | D25: شركة البرج الخرساني لخلاطة الاسمنت | E25: بيع وقود الديزل | F25: تزويد بمنتج الديزل | G25: 46260 | H25: 46264 | I25: 46628 | J25: =IF(B25="","",MAX(I25,_xlfn.MAXIFS(التمديدات!$C$2:$C$301,التمديدات!$A$2:$A$301,B25))) -> 46628 | K25: =IF(OR(H25="",I25=""),"",ROUND((I25-H25)/30.4,0)) -> 12 | N25: 242108لتر | O25: إدارة المبيعات | R25: =IF(B25="","",IF(Q25<>"",Q25,IF(H25>TODAY(),"لم يبدأ بعد",IF(J25<TODAY(),"منتهٍ",IF(J25-TODAY()<='القوائم والإعدادات'!$E$2,"قريب الانتهاء","ساري"))))) -> ساري | S25: =IF(B25="","",J25-TODAY()) -> 320 | T25: =IF(OR(R25="ساري",R25="قريب الانتهاء"),IF(S25<='القوائم والإعدادات'!$E$4,"عاجل",IF(S25<='القوائم والإعدادات'!$E$3,"خلال 60 يوم",IF(S25<='القوائم والإعدادات'!$E$2,"خلال 90 يوم",""))),"") | U25: =IF(B25="","",COUNTIF(التمديدات!$A$2:$A$301,B25)) -> 0 | X25: =IF(B25="","",IF(COUNTIFS($B$2:$B$501,B25,$D$2:$D$501,D25)>1,"مكرر!",""))
A26: 25 | B26: ع.ت.د /668 | C26: طرابلس | D26: شركة الإنفتاح للمقاولات العامة والطرق والاستثمار | E26: بيع وقود الديزل | F26: تزويد بمنتج الديزل | G26: 46258 | H26: 46264 | I26: 46628 | J26: =IF(B26="","",MAX(I26,_xlfn.MAXIFS(التمديدات!$C$2:$C$301,التمديدات!$A$2:$A$301,B26))) -> 46628 | K26: =IF(OR(H26="",I26=""),"",ROUND((I26-H26)/30.4,0)) -> 12 | N26: 234400لتر | O26: إدارة المبيعات | R26: =IF(B26="","",IF(Q26<>"",Q26,IF(H26>TODAY(),"لم يبدأ بعد",IF(J26<TODAY(),"منتهٍ",IF(J26-TODAY()<='القوائم والإعدادات'!$E$2,"قريب الانتهاء","ساري"))))) -> ساري | S26: =IF(B26="","",J26-TODAY()) -> 320 | T26: =IF(OR(R26="ساري",R26="قريب الانتهاء"),IF(S26<='القوائم والإعدادات'!$E$4,"عاجل",IF(S26<='القوائم والإعدادات'!$E$3,"خلال 60 يوم",IF(S26<='القوائم والإعدادات'!$E$2,"خلال 90 يوم",""))),"") | U26: =IF(B26="","",COUNTIF(التمديدات!$A$2:$A$301,B26)) -> 0 | X26: =IF(B26="","",IF(COUNTIFS($B$2:$B$501,B26,$D$2:$D$501,D26)>1,"مكرر!",""))
A27: 26 | B27: ع.ت.د /631 | C27: مصراته | D27: مصنع مصراته لصناعة الأنابيب | E27: بيع وقود الديزل | F27: تزويد بمنتج الديزل | G27: 46247 | H27: 46252 | I27: 46616 | J27: =IF(B27="","",MAX(I27,_xlfn.MAXIFS(التمديدات!$C$2:$C$301,التمديدات!$A$2:$A$301,B27))) -> 46616 | K27: =IF(OR(H27="",I27=""),"",ROUND((I27-H27)/30.4,0)) -> 12 | N27: 16540لتر | R27: =IF(B27="","",IF(Q27<>"",Q27,IF(H27>TODAY(),"لم يبدأ بعد",IF(J27<TODAY(),"منتهٍ",IF(J27-TODAY()<='القوائم والإعدادات'!$E$2,"قريب الانتهاء","ساري"))))) -> ساري | S27: =IF(B27="","",J27-TODAY()) -> 308 | T27: =IF(OR(R27="ساري",R27="قريب الانتهاء"),IF(S27<='القوائم والإعدادات'!$E$4,"عاجل",IF(S27<='القوائم والإعدادات'!$E$3,"خلال 60 يوم",IF(S27<='القوائم والإعدادات'!$E$2,"خلال 90 يوم",""))),"") | U27: =IF(B27="","",COUNTIF(التمديدات!$A$2:$A$301,B27)) -> 0 | X27: =IF(B27="","",IF(COUNTIFS($B$2:$B$501,B27,$D$2:$D$501,D27)>1,"مكرر!",""))
A28: 27 | B28: ع.ت.د /677 | C28: سرت | D28: مستشفى بن سينا التعليمي سرت | E28: بيع وقود الديزل | F28: تزويد بمنتج الديزل | G28: 46264 | H28: 46266 | I28: 46630 | J28: =IF(B28="","",MAX(I28,_xlfn.MAXIFS(التمديدات!$C$2:$C$301,التمديدات!$A$2:$A$301,B28))) -> 46630 | K28: =IF(OR(H28="",I28=""),"",ROUND((I28-H28)/30.4,0)) -> 12 | N28: 89500لتر | R28: =IF(B28="","",IF(Q28<>"",Q28,IF(H28>TODAY(),"لم يبدأ بعد",IF(J28<TODAY(),"منتهٍ",IF(J28-TODAY()<='القوائم والإعدادات'!$E$2,"قريب الانتهاء","ساري"))))) -> ساري | S28: =IF(B28="","",J28-TODAY()) -> 322 | T28: =IF(OR(R28="ساري",R28="قريب الانتهاء"),IF(S28<='القوائم والإعدادات'!$E$4,"عاجل",IF(S28<='القوائم والإعدادات'!$E$3,"خلال 60 يوم",IF(S28<='القوائم والإعدادات'!$E$2,"خلال 90 يوم",""))),"") | U28: =IF(B28="","",COUNTIF(التمديدات!$A$2:$A$301,B28)) -> 0 | X28: =IF(B28="","",IF(COUNTIFS($B$2:$B$501,B28,$D$2:$D$501,D28)>1,"مكرر!",""))
A29: 28 | B29: ع.ت.د /641 | C29: مصراته | D29: شركة إنفاق الجبال للمقاولات العامة والاستثمار العقاري | E29: بيع وقود الديزل | F29: تزويد بمنتج الديزل | G29: 46251 | H29: 46253 | I29: 46617 | J29: =IF(B29="","",MAX(I29,_xlfn.MAXIFS(التمديدات!$C$2:$C$301,التمديدات!$A$2:$A$301,B29))) -> 46617 | K29: =IF(OR(H29="",I29=""),"",ROUND((I29-H29)/30.4,0)) -> 12 | N29: 178000لتر | R29: =IF(B29="","",IF(Q29<>"",Q29,IF(H29>TODAY(),"لم يبدأ بعد",IF(J29<TODAY(),"منتهٍ",IF(J29-TODAY()<='القوائم والإعدادات'!$E$2,"قريب الانتهاء","ساري"))))) -> ساري | S29: =IF(B29="","",J29-TODAY()) -> 309 | T29: =IF(OR(R29="ساري",R29="قريب الانتهاء"),IF(S29<='القوائم والإعدادات'!$E$4,"عاجل",IF(S29<='القوائم والإعدادات'!$E$3,"خلال 60 يوم",IF(S29<='القوائم والإعدادات'!$E$2,"خلال 90 يوم",""))),"") | U29: =IF(B29="","",COUNTIF(التمديدات!$A$2:$A$301,B29)) -> 0 | X29: =IF(B29="","",IF(COUNTIFS($B$2:$B$501,B29,$D$2:$D$501,D29)>1,"مكرر!",""))
A30: 29 | B30: ع.ت.د /689 | C30: طرابلس | D30: شركة السهل الأخضر لانتاج الشرشور ومواد البناء | E30: بيع وقود الديزل | F30: تزويد بمنتج الديزل | G30: 46264 | H30: 46267 | I30: 46631 | J30: =IF(B30="","",MAX(I30,_xlfn.MAXIFS(التمديدات!$C$2:$C$301,التمديدات!$A$2:$A$301,B30))) -> 46631 | K30: =IF(OR(H30="",I30=""),"",ROUND((I30-H30)/30.4,0)) -> 12 | N30: 47793لتر | R30: =IF(B30="","",IF(Q30<>"",Q30,IF(H30>TODAY(),"لم يبدأ بعد",IF(J30<TODAY(),"منتهٍ",IF(J30-TODAY()<='القوائم والإعدادات'!$E$2,"قريب الانتهاء","ساري"))))) -> ساري | S30: =IF(B30="","",J30-TODAY()) -> 323 | T30: =IF(OR(R30="ساري",R30="قريب الانتهاء"),IF(S30<='القوائم والإعدادات'!$E$4,"عاجل",IF(S30<='القوائم والإعدادات'!$E$3,"خلال 60 يوم",IF(S30<='القوائم والإعدادات'!$E$2,"خلال 90 يوم",""))),"") | U30: =IF(B30="","",COUNTIF(التمديدات!$A$2:$A$301,B30)) -> 0 | X30: =IF(B30="","",IF(COUNTIFS($B$2:$B$501,B30,$D$2:$D$501,D30)>1,"مكرر!",""))
A31: 30 | B31: ع.ت.د /652 | C31: زليتن | D31: شركة المقاول لصناعة مواد البناء وصناعة الاجر | E31: بيع وقود الديزل | F31: تزويد بمنتج الديزل | G31: 46252 | H31: 46254 | I31: 46618 | J31: =IF(B31="","",MAX(I31,_xlfn.MAXIFS(التمديدات!$C$2:$C$301,التمديدات!$A$2:$A$301,B31))) -> 46618 | K31: =IF(OR(H31="",I31=""),"",ROUND((I31-H31)/30.4,0)) -> 12 | N31: 49800لتر | R31: =IF(B31="","",IF(Q31<>"",Q31,IF(H31>TODAY(),"لم يبدأ بعد",IF(J31<TODAY(),"منتهٍ",IF(J31-TODAY()<='القوائم والإعدادات'!$E$2,"قريب الانتهاء","ساري"))))) -> ساري | S31: =IF(B31="","",J31-TODAY()) -> 310 | T31: =IF(OR(R31="ساري",R31="قريب الانتهاء"),IF(S31<='القوائم والإعدادات'!$E$4,"عاجل",IF(S31<='القوائم والإعدادات'!$E$3,"خلال 60 يوم",IF(S31<='القوائم والإعدادات'!$E$2,"خلال 90 يوم",""))),"") | U31: =IF(B31="","",COUNTIF(التمديدات!$A$2:$A$301,B31)) -> 0 | X31: =IF(B31="","",IF(COUNTIFS($B$2:$B$501,B31,$D$2:$D$501,D31)>1,"مكرر!",""))
A32: 31 | B32: ع.ت.د /648 | C32: زليتن | D32: شركة تكنو لصناعة مواد البناء | E32: بيع وقود الديزل | F32: تزويد بمنتج الديزل | G32: 46252 | H32: 46253 | I32: 46617 | J32: =IF(B32="","",MAX(I32,_xlfn.MAXIFS(التمديدات!$C$2:$C$301,التمديدات!$A$2:$A$301,B32))) -> 46617 | K32: =IF(OR(H32="",I32=""),"",ROUND((I32-H32)/30.4,0)) -> 12 | N32: 64600لتر | R32: =IF(B32="","",IF(Q32<>"",Q32,IF(H32>TODAY(),"لم يبدأ بعد",IF(J32<TODAY(),"منتهٍ",IF(J32-TODAY()<='القوائم والإعدادات'!$E$2,"قريب الانتهاء","ساري"))))) -> ساري | S32: =IF(B32="","",J32-TODAY()) -> 309 | T32: =IF(OR(R32="ساري",R32="قريب الانتهاء"),IF(S32<='القوائم والإعدادات'!$E$4,"عاجل",IF(S32<='القوائم والإعدادات'!$E$3,"خلال 60 يوم",IF(S32<='القوائم والإعدادات'!$E$2,"خلال 90 يوم",""))),"") | U32: =IF(B32="","",COUNTIF(التمديدات!$A$2:$A$301,B32)) -> 0 | X32: =IF(B32="","",IF(COUNTIFS($B$2:$B$501,B32,$D$2:$D$501,D32)>1,"مكرر!",""))
A33: 32 | B33: ع.ت.د /104 | C33: مصراته | D33: شركة المناجم للصناعات المعدنية | E33: بيع وقود الديزل | F33: تزويد بمنتج الديزل | G33: 46267 | H33: 46268 | I33: 46632 | J33: =IF(B33="","",MAX(I33,_xlfn.MAXIFS(التمديدات!$C$2:$C$301,التمديدات!$A$2:$A$301,B33))) -> 46632 | K33: =IF(OR(H33="",I33=""),"",ROUND((I33-H33)/30.4,0)) -> 12 | N33: 181900لتر | R33: =IF(B33="","",IF(Q33<>"",Q33,IF(H33>TODAY(),"لم يبدأ بعد",IF(J33<TODAY(),"منتهٍ",IF(J33-TODAY()<='القوائم والإعدادات'!$E$2,"قريب الانتهاء","ساري"))))) -> ساري | S33: =IF(B33="","",J33-TODAY()) -> 324 | T33: =IF(OR(R33="ساري",R33="قريب الانتهاء"),IF(S33<='القوائم والإعدادات'!$E$4,"عاجل",IF(S33<='القوائم والإعدادات'!$E$3,"خلال 60 يوم",IF(S33<='القوائم والإعدادات'!$E$2,"خلال 90 يوم",""))),"") | U33: =IF(B33="","",COUNTIF(التمديدات!$A$2:$A$301,B33)) -> 0 | X33: =IF(B33="","",IF(COUNTIFS($B$2:$B$501,B33,$D$2:$D$501,D33)>1,"مكرر!",""))
A34: 33 | B34: ع.ت.د /682 | C34: مصراته | D34: شركة الدجاجة السعيدة لتربية وذبح وتسويق الدواجن | E34: بيع وقود الديزل | F34: تزويد بمنتج الديزل | G34: 46261 | H34: 46266 | I34: 46630 | J34: =IF(B34="","",MAX(I34,_xlfn.MAXIFS(التمديدات!$C$2:$C$301,التمديدات!$A$2:$A$301,B34))) -> 46630 | K34: =IF(OR(H34="",I34=""),"",ROUND((I34-H34)/30.4,0)) -> 12 | N34: 48065لتر | R34: =IF(B34="","",IF(Q34<>"",Q34,IF(H34>TODAY(),"لم يبدأ بعد",IF(J34<TODAY(),"منتهٍ",IF(J34-TODAY()<='القوائم والإعدادات'!$E$2,"قريب الانتهاء","ساري"))))) -> ساري | S34: =IF(B34="","",J34-TODAY()) -> 322 | T34: =IF(OR(R34="ساري",R34="قريب الانتهاء"),IF(S34<='القوائم والإعدادات'!$E$4,"عاجل",IF(S34<='القوائم والإعدادات'!$E$3,"خلال 60 يوم",IF(S34<='القوائم والإعدادات'!$E$2,"خلال 90 يوم",""))),"") | U34: =IF(B34="","",COUNTIF(التمديدات!$A$2:$A$301,B34)) -> 0 | X34: =IF(B34="","",IF(COUNTIFS($B$2:$B$501,B34,$D$2:$D$501,D34)>1,"مكرر!",""))
A35: 34 | B35: ع.ت.د /546 | C35: مصراته | D35: شركة ابوفارس وشركاؤه للصناعات الحديدية | E35: بيع وقود الديزل | F35: تزويد بمنتج الديزل | G35: 46250 | H35: 46253 | I35: 46617 | J35: =IF(B35="","",MAX(I35,_xlfn.MAXIFS(التمديدات!$C$2:$C$301,التمديدات!$A$2:$A$301,B35))) -> 46617 | K35: =IF(OR(H35="",I35=""),"",ROUND((I35-H35)/30.4,0)) -> 12 | N35: 52700لتر | R35: =IF(B35="","",IF(Q35<>"",Q35,IF(H35>TODAY(),"لم يبدأ بعد",IF(J35<TODAY(),"منتهٍ",IF(J35-TODAY()<='القوائم والإعدادات'!$E$2,"قريب الانتهاء","ساري"))))) -> ساري | S35: =IF(B35="","",J35-TODAY()) -> 309 | T35: =IF(OR(R35="ساري",R35="قريب الانتهاء"),IF(S35<='القوائم والإعدادات'!$E$4,"عاجل",IF(S35<='القوائم والإعدادات'!$E$3,"خلال 60 يوم",IF(S35<='القوائم والإعدادات'!$E$2,"خلال 90 يوم",""))),"") | U35: =IF(B35="","",COUNTIF(التمديدات!$A$2:$A$301,B35)) -> 0 | X35: =IF(B35="","",IF(COUNTIFS($B$2:$B$501,B35,$D$2:$D$501,D35)>1,"مكرر!",""))
A36: 35 | B36: ع.ت.د /680 | C36: زليتن | D36: شركة ارزاق الخير لصناعة المواد الغذائية | E36: بيع وقود الديزل | F36: تزويد بمنتج الديزل | G36: 46260 | H36: 46266 | I36: 46630 | J36: =IF(B36="","",MAX(I36,_xlfn.MAXIFS(التمديدات!$C$2:$C$301,التمديدات!$A$2:$A$301,B36))) -> 46630 | K36: =IF(OR(H36="",I36=""),"",ROUND((I36-H36)/30.4,0)) -> 12 | N36: 110540لتر | R36: =IF(B36="","",IF(Q36<>"",Q36,IF(H36>TODAY(),"لم يبدأ بعد",IF(J36<TODAY(),"منتهٍ",IF(J36-TODAY()<='القوائم والإعدادات'!$E$2,"قريب الانتهاء","ساري"))))) -> ساري | S36: =IF(B36="","",J36-TODAY()) -> 322 | T36: =IF(OR(R36="ساري",R36="قريب الانتهاء"),IF(S36<='القوائم والإعدادات'!$E$4,"عاجل",IF(S36<='القوائم والإعدادات'!$E$3,"خلال 60 يوم",IF(S36<='القوائم والإعدادات'!$E$2,"خلال 90 يوم",""))),"") | U36: =IF(B36="","",COUNTIF(التمديدات!$A$2:$A$301,B36)) -> 0 | X36: =IF(B36="","",IF(COUNTIFS($B$2:$B$501,B36,$D$2:$D$501,D36)>1,"مكرر!",""))
A37: 36 | B37: ع.ت.د /639 | C37: مصراته | D37: شركة المجمع الاستثماري لصناعة مواد البناء | E37: بيع وقود الديزل | F37: تزويد بمنتج الديزل | G37: 46251 | H37: 46253 | I37: 46617 | J37: =IF(B37="","",MAX(I37,_xlfn.MAXIFS(التمديدات!$C$2:$C$301,التمديدات!$A$2:$A$301,B37))) -> 46617 | K37: =IF(OR(H37="",I37=""),"",ROUND((I37-H37)/30.4,0)) -> 12 | N37: 61000لتر | R37: =IF(B37="","",IF(Q37<>"",Q37,IF(H37>TODAY(),"لم يبدأ بعد",IF(J37<TODAY(),"منتهٍ",IF(J37-TODAY()<='القوائم والإعدادات'!$E$2,"قريب الانتهاء","ساري"))))) -> ساري | S37: =IF(B37="","",J37-TODAY()) -> 309 | T37: =IF(OR(R37="ساري",R37="قريب الانتهاء"),IF(S37<='القوائم والإعدادات'!$E$4,"عاجل",IF(S37<='القوائم والإعدادات'!$E$3,"خلال 60 يوم",IF(S37<='القوائم والإعدادات'!$E$2,"خلال 90 يوم",""))),"") | U37: =IF(B37="","",COUNTIF(التمديدات!$A$2:$A$301,B37)) -> 0 | X37: =IF(B37="","",IF(COUNTIFS($B$2:$B$501,B37,$D$2:$D$501,D37)>1,"مكرر!",""))
A38: 37 | B38: ع.ت.د /341 | C38: نسمة | D38: شركة الإعمار الأجدر للخدمات النفطية | E38: بيع وقود الديزل | F38: تزويد بمنتج الديزل | G38: 46237 | H38: 46239 | I38: 46603 | J38: =IF(B38="","",MAX(I38,_xlfn.MAXIFS(التمديدات!$C$2:$C$301,التمديدات!$A$2:$A$301,B38))) -> 46603 | K38: =IF(OR(H38="",I38=""),"",ROUND((I38-H38)/30.4,0)) -> 12 | R38: =IF(B38="","",IF(Q38<>"",Q38,IF(H38>TODAY(),"لم يبدأ بعد",IF(J38<TODAY(),"منتهٍ",IF(J38-TODAY()<='القوائم والإعدادات'!$E$2,"قريب الانتهاء","ساري"))))) -> ساري | S38: =IF(B38="","",J38-TODAY()) -> 295 | T38: =IF(OR(R38="ساري",R38="قريب الانتهاء"),IF(S38<='القوائم والإعدادات'!$E$4,"عاجل",IF(S38<='القوائم والإعدادات'!$E$3,"خلال 60 يوم",IF(S38<='القوائم والإعدادات'!$E$2,"خلال 90 يوم",""))),"") | U38: =IF(B38="","",COUNTIF(التمديدات!$A$2:$A$301,B38)) -> 0 | X38: =IF(B38="","",IF(COUNTIFS($B$2:$B$501,B38,$D$2:$D$501,D38)>1,"مكرر!",""))
A39: 38 | B39: ع.ت.د /616 | C39: البحر | D39: وحدة الصيد المسماة زرقاء | E39: بيع وقود السفن | F39: تزويد بمنتج وقود السفن | G39: 46244 | H39: 46250 | I39: 46614 | J39: =IF(B39="","",MAX(I39,_xlfn.MAXIFS(التمديدات!$C$2:$C$301,التمديدات!$A$2:$A$301,B39))) -> 46614 | K39: =IF(OR(H39="",I39=""),"",ROUND((I39-H39)/30.4,0)) -> 12 | R39: =IF(B39="","",IF(Q39<>"",Q39,IF(H39>TODAY(),"لم يبدأ بعد",IF(J39<TODAY(),"منتهٍ",IF(J39-TODAY()<='القوائم والإعدادات'!$E$2,"قريب الانتهاء","ساري"))))) -> ساري | S39: =IF(B39="","",J39-TODAY()) -> 306 | T39: =IF(OR(R39="ساري",R39="قريب الانتهاء"),IF(S39<='القوائم والإعدادات'!$E$4,"عاجل",IF(S39<='القوائم والإعدادات'!$E$3,"خلال 60 يوم",IF(S39<='القوائم والإعدادات'!$E$2,"خلال 90 يوم",""))),"") | U39: =IF(B39="","",COUNTIF(التمديدات!$A$2:$A$301,B39)) -> 0 | X39: =IF(B39="","",IF(COUNTIFS($B$2:$B$501,B39,$D$2:$D$501,D39)>1,"مكرر!",""))
A40: 39 | B40: ع.ت.د /615 | C40: البحر | D40: وحدة الصيد المسماة لبدة | E40: بيع وقود السفن | F40: تزويد بمنتج وقود السفن | G40: 46244 | H40: 46250 | I40: 46614 | J40: =IF(B40="","",MAX(I40,_xlfn.MAXIFS(التمديدات!$C$2:$C$301,التمديدات!$A$2:$A$301,B40))) -> 46614 | K40: =IF(OR(H40="",I40=""),"",ROUND((I40-H40)/30.4,0)) -> 12 | R40: =IF(B40="","",IF(Q40<>"",Q40,IF(H40>TODAY(),"لم يبدأ بعد",IF(J40<TODAY(),"منتهٍ",IF(J40-TODAY()<='القوائم والإعدادات'!$E$2,"قريب الانتهاء","ساري"))))) -> ساري | S40: =IF(B40="","",J40-TODAY()) -> 306 | T40: =IF(OR(R40="ساري",R40="قريب الانتهاء"),IF(S40<='القوائم والإعدادات'!$E$4,"عاجل",IF(S40<='القوائم والإعدادات'!$E$3,"خلال 60 يوم",IF(S40<='القوائم والإعدادات'!$E$2,"خلال 90 يوم",""))),"") | U40: =IF(B40="","",COUNTIF(التمديدات!$A$2:$A$301,B40)) -> 0 | X40: =IF(B40="","",IF(COUNTIFS($B$2:$B$501,B40,$D$2:$D$501,D40)>1,"مكرر!",""))
...

Sheet الشركات
A1: اسم الشركة | B1: الهاتف | C1: البريد الإلكتروني | D1: العنوان | E1: عدد العقود | F1: العقود السارية
A2: شركة الأفق للخدمات النفطية | B2: 0910000001 | C2: info@example.test | D2: طرابلس (بيانات وهمية) | E2: =IF(A2="","",COUNTIF(العقود!$D$2:$D$501,A2)) -> 0 | F2: =IF(A2="","",COUNTIFS(العقود!$D$2:$D$501,A2,العقود!$R$2:$R$501,"ساري")+COUNTIFS(العقود!$D$2:$D$501,A2,العقود!$R$2:$R$501,"قريب الانتهاء")) -> 0
A3: شركة النور للنقل والتشغيل | B3: 0910000002 | C3: info@example.test | D3: طرابلس (بيانات وهمية) | E3: =IF(A3="","",COUNTIF(العقود!$D$2:$D$501,A3)) -> 0 | F3: =IF(A3="","",COUNTIFS(العقود!$D$2:$D$501,A3,العقود!$R$2:$R$501,"ساري")+COUNTIFS(العقود!$D$2:$D$501,A3,العقود!$R$2:$R$501,"قريب الانتهاء")) -> 0
A4: شركة المدار للتوريدات | B4: 0910000003 | C4: info@example.test | D4: طرابلس (بيانات وهمية) | E4: =IF(A4="","",COUNTIF(العقود!$D$2:$D$501,A4)) -> 0 | F4: =IF(A4="","",COUNTIFS(العقود!$D$2:$D$501,A4,العقود!$R$2:$R$501,"ساري")+COUNTIFS(العقود!$D$2:$D$501,A4,العقود!$R$2:$R$501,"قريب الانتهاء")) -> 0
A5: شركة الساحل للصيانة | B5: 0910000004 | C5: info@example.test | D5: طرابلس (بيانات وهمية) | E5: =IF(A5="","",COUNTIF(العقود!$D$2:$D$501,A5)) -> 0 | F5: =IF(A5="","",COUNTIFS(العقود!$D$2:$D$501,A5,العقود!$R$2:$R$501,"ساري")+COUNTIFS(العقود!$D$2:$D$501,A5,العقود!$R$2:$R$501,"قريب الانتهاء")) -> 0
A6: شركة الواحة للتجارة العامة | B6: 0910000005 | C6: info@example.test | D6: طرابلس (بيانات وهمية) | E6: =IF(A6="","",COUNTIF(العقود!$D$2:$D$501,A6)) -> 0 | F6: =IF(A6="","",COUNTIFS(العقود!$D$2:$D$501,A6,العقود!$R$2:$R$501,"ساري")+COUNTIFS(العقود!$D$2:$D$501,A6,العقود!$R$2:$R$501,"قريب الانتهاء")) -> 0
A7: شركة الريادة للطاقة | B7: 0910000006 | C7: info@example.test | D7: طرابلس (بيانات وهمية) | E7: =IF(A7="","",COUNTIF(العقود!$D$2:$D$501,A7)) -> 0 | F7: =IF(A7="","",COUNTIFS(العقود!$D$2:$D$501,A7,العقود!$R$2:$R$501,"ساري")+COUNTIFS(العقود!$D$2:$D$501,A7,العقود!$R$2:$R$501,"قريب الانتهاء")) -> 0
E8: =IF(A8="","",COUNTIF(العقود!$D$2:$D$501,A8)) | F8: =IF(A8="","",COUNTIFS(العقود!$D$2:$D$501,A8,العقود!$R$2:$R$501,"ساري")+COUNTIFS(العقود!$D$2:$D$501,A8,العقود!$R$2:$R$501,"قريب الانتهاء"))
E9: =IF(A9="","",COUNTIF(العقود!$D$2:$D$501,A9)) | F9: =IF(A9="","",COUNTIFS(العقود!$D$2:$D$501,A9,العقود!$R$2:$R$501,"ساري")+COUNTIFS(العقود!$D$2:$D$501,A9,العقود!$R$2:$R$501,"قريب الانتهاء"))
E10: =IF(A10="","",COUNTIF(العقود!$D$2:$D$501,A10)) | F10: =IF(A10="","",COUNTIFS(العقود!$D$2:$D$501,A10,العقود!$R$2:$R$501,"ساري")+COUNTIFS(العقود!$D$2:$D$501,A10,العقود!$R$2:$R$501,"قريب الانتهاء"))
E11: =IF(A11="","",COUNTIF(العقود!$D$2:$D$501,A11)) | F11: =IF(A11="","",COUNTIFS(العقود!$D$2:$D$501,A11,العقود!$R$2:$R$501,"ساري")+COUNTIFS(العقود!$D$2:$D$501,A11,العقود!$R$2:$R$501,"قريب الانتهاء"))
E12: =IF(A12="","",COUNTIF(العقود!$D$2:$D$501,A12)) | F12: =IF(A12="","",COUNTIFS(العقود!$D$2:$D$501,A12,العقود!$R$2:$R$501,"ساري")+COUNTIFS(العقود!$D$2:$D$501,A12,العقود!$R$2:$R$501,"قريب الانتهاء"))
E13: =IF(A13="","",COUNTIF(العقود!$D$2:$D$501,A13)) | F13: =IF(A13="","",COUNTIFS(العقود!$D$2:$D$501,A13,العقود!$R$2:$R$501,"ساري")+COUNTIFS(العقود!$D$2:$D$501,A13,العقود!$R$2:$R$501,"قريب الانتهاء"))
E14: =IF(A14="","",COUNTIF(العقود!$D$2:$D$501,A14)) | F14: =IF(A14="","",COUNTIFS(العقود!$D$2:$D$501,A14,العقود!$R$2:$R$501,"ساري")+COUNTIFS(العقود!$D$2:$D$501,A14,العقود!$R$2:$R$501,"قريب الانتهاء"))
E15: =IF(A15="","",COUNTIF(العقود!$D$2:$D$501,A15)) | F15: =IF(A15="","",COUNTIFS(العقود!$D$2:$D$501,A15,العقود!$R$2:$R$501,"ساري")+COUNTIFS(العقود!$D$2:$D$501,A15,العقود!$R$2:$R$501,"قريب الانتهاء"))
E16: =IF(A16="","",COUNTIF(العقود!$D$2:$D$501,A16)) | F16: =IF(A16="","",COUNTIFS(العقود!$D$2:$D$501,A16,العقود!$R$2:$R$501,"ساري")+COUNTIFS(العقود!$D$2:$D$501,A16,العقود!$R$2:$R$501,"قريب الانتهاء"))
E17: =IF(A17="","",COUNTIF(العقود!$D$2:$D$501,A17)) | F17: =IF(A17="","",COUNTIFS(العقود!$D$2:$D$501,A17,العقود!$R$2:$R$501,"ساري")+COUNTIFS(العقود!$D$2:$D$501,A17,العقود!$R$2:$R$501,"قريب الانتهاء"))
E18: =IF(A18="","",COUNTIF(العقود!$D$2:$D$501,A18)) | F18: =IF(A18="","",COUNTIFS(العقود!$D$2:$D$501,A18,العقود!$R$2:$R$501,"ساري")+COUNTIFS(العقود!$D$2:$D$501,A18,العقود!$R$2:$R$501,"قريب الانتهاء"))
E19: =IF(A19="","",COUNTIF(العقود!$D$2:$D$501,A19)) | F19: =IF(A19="","",COUNTIFS(العقود!$D$2:$D$501,A19,العقود!$R$2:$R$501,"ساري")+COUNTIFS(العقود!$D$2:$D$501,A19,العقود!$R$2:$R$501,"قريب الانتهاء"))
... E101: =IF(A101="","",COUNTIF(العقود!$D$2:$D$501,A101)) | F101: =IF(A101="","",COUNTIFS(العقود!$D$2:$D$501,A101,العقود!$R$2:$R$501,"ساري")+COUNTIFS(العقود!$D$2:$D$501,A101,العقود!$R$2:$R$501,"قريب الانتهاء"))

Sheet التمديدات
A1: رقم العقد | B1: تاريخ قرار التمديد | C1: تاريخ الانتهاء الجديد | D1: ملاحظة | F1: (عمود مساعد)
A2: ع/2024/103 | B2: 46176 | C2: 46386 | D2: تمديد ثلاثة أشهر (مثال) | F2: =IF(A2='بطاقة العقد'!$B$1,ROW(),"")
A3: ع/2024/106 | B3: 46321 | C3: 46546 | D3: تمديد ثمانية أشهر (مثال) | F3: =IF(A3='بطاقة العقد'!$B$1,ROW(),"")
F4: =IF(A4='بطاقة العقد'!$B$1,ROW(),"")
F5: =IF(A5='بطاقة العقد'!$B$1,ROW(),"")
F6: =IF(A6='بطاقة العقد'!$B$1,ROW(),"")
F7: =IF(A7='بطاقة العقد'!$B$1,ROW(),"")
F8: =IF(A8='بطاقة العقد'!$B$1,ROW(),"")
F9: =IF(A9='بطاقة العقد'!$B$1,ROW(),"")
F10: =IF(A10='بطاقة العقد'!$B$1,ROW(),"")
F11: =IF(A11='بطاقة العقد'!$B$1,ROW(),"")
F12: =IF(A12='بطاقة العقد'!$B$1,ROW(),"")
F13: =IF(A13='بطاقة العقد'!$B$1,ROW(),"")
F14: =IF(A14='بطاقة العقد'!$B$1,ROW(),"")
F15: =IF(A15='بطاقة العقد'!$B$1,ROW(),"")
... F301: =IF(A301='بطاقة العقد'!$B$1,ROW(),"")

Sheet المراسلات
A1: رقم العقد | B1: رقم المراسلة | C1: تاريخ المراسلة | D1: ملاحظة | F1: (عمود مساعد)
A2: ع/2025/101 | B2: م/301 | C2: 45606 | D2: مخاطبة بخصوص العقد (مثال) | F2: =IF(A2='بطاقة العقد'!$B$1,ROW(),"")
A3: ع/2025/104 | B3: م/304 | C3: 46206 | D3: إخطار بقرب الانتهاء (مثال) | F3: =IF(A3='بطاقة العقد'!$B$1,ROW(),"") -> 3
F4: =IF(A4='بطاقة العقد'!$B$1,ROW(),"")
F5: =IF(A5='بطاقة العقد'!$B$1,ROW(),"")
F6: =IF(A6='بطاقة العقد'!$B$1,ROW(),"")
F7: =IF(A7='بطاقة العقد'!$B$1,ROW(),"")
F8: =IF(A8='بطاقة العقد'!$B$1,ROW(),"")
F9: =IF(A9='بطاقة العقد'!$B$1,ROW(),"")
F10: =IF(A10='بطاقة العقد'!$B$1,ROW(),"")
F11: =IF(A11='بطاقة العقد'!$B$1,ROW(),"")
F12: =IF(A12='بطاقة العقد'!$B$1,ROW(),"")
F13: =IF(A13='بطاقة العقد'!$B$1,ROW(),"")
F14: =IF(A14='بطاقة العقد'!$B$1,ROW(),"")
F15: =IF(A15='بطاقة العقد'!$B$1,ROW(),"")
... F301: =IF(A301='بطاقة العقد'!$B$1,ROW(),"")

Sheet بطاقة العقد
A1: أدخل رقم العقد ← | B1: ع/2025/104 | C1: (يُؤخذ أول عقد بهذا الرقم)
A3: الشركة المتعاقدة | B3: =IFERROR(IF(INDEX(العقود!$D$2:$D$501,MATCH($B$1,العقود!$B$2:$B$501,0))="","—",INDEX(العقود!$D$2:$D$501,MATCH($B$1,العقود!$B$2:$B$501,0))),"غير موجود") -> غير موجود
A4: نوع العقد | B4: =IFERROR(IF(INDEX(العقود!$E$2:$E$501,MATCH($B$1,العقود!$B$2:$B$501,0))="","—",INDEX(العقود!$E$2:$E$501,MATCH($B$1,العقود!$B$2:$B$501,0))),"غير موجود") -> غير موجود
A5: الموضوع | B5: =IFERROR(IF(INDEX(العقود!$F$2:$F$501,MATCH($B$1,العقود!$B$2:$B$501,0))="","—",INDEX(العقود!$F$2:$F$501,MATCH($B$1,العقود!$B$2:$B$501,0))),"غير موجود") -> غير موجود
A6: الرقم المرجعي | B6: =IFERROR(IF(INDEX(العقود!$C$2:$C$501,MATCH($B$1,العقود!$B$2:$B$501,0))="","—",INDEX(العقود!$C$2:$C$501,MATCH($B$1,العقود!$B$2:$B$501,0))),"غير موجود") -> غير موجود
A7: تاريخ التوقيع | B7: =IFERROR(IF(INDEX(العقود!$G$2:$G$501,MATCH($B$1,العقود!$B$2:$B$501,0))="","—",INDEX(العقود!$G$2:$G$501,MATCH($B$1,العقود!$B$2:$B$501,0))),"غير موجود") -> غير موجود
A8: بداية السريان | B8: =IFERROR(IF(INDEX(العقود!$H$2:$H$501,MATCH($B$1,العقود!$B$2:$B$501,0))="","—",INDEX(العقود!$H$2:$H$501,MATCH($B$1,العقود!$B$2:$B$501,0))),"غير موجود") -> غير موجود
A9: الانتهاء الأصلي | B9: =IFERROR(IF(INDEX(العقود!$I$2:$I$501,MATCH($B$1,العقود!$B$2:$B$501,0))="","—",INDEX(العقود!$I$2:$I$501,MATCH($B$1,العقود!$B$2:$B$501,0))),"غير موجود") -> غير موجود
A10: الانتهاء الفعلي | B10: =IFERROR(IF(INDEX(العقود!$J$2:$J$501,MATCH($B$1,العقود!$B$2:$B$501,0))="","—",INDEX(العقود!$J$2:$J$501,MATCH($B$1,العقود!$B$2:$B$501,0))),"غير موجود") -> غير موجود
A11: المدة الأصلية (شهر) | B11: =IFERROR(IF(INDEX(العقود!$K$2:$K$501,MATCH($B$1,العقود!$B$2:$B$501,0))="","—",INDEX(العقود!$K$2:$K$501,MATCH($B$1,العقود!$B$2:$B$501,0))),"غير موجود") -> غير موجود
A12: المتبقي (يوم) | B12: =IFERROR(IF(INDEX(العقود!$S$2:$S$501,MATCH($B$1,العقود!$B$2:$B$501,0))="","—",INDEX(العقود!$S$2:$S$501,MATCH($B$1,العقود!$B$2:$B$501,0))),"غير موجود") -> غير موجود
A13: الحالة | B13: =IFERROR(IF(INDEX(العقود!$R$2:$R$501,MATCH($B$1,العقود!$B$2:$B$501,0))="","—",INDEX(العقود!$R$2:$R$501,MATCH($B$1,العقود!$B$2:$B$501,0))),"غير موجود") -> غير موجود
A14: عدد التمديدات | B14: =IFERROR(IF(INDEX(العقود!$U$2:$U$501,MATCH($B$1,العقود!$B$2:$B$501,0))="","—",INDEX(العقود!$U$2:$U$501,MATCH($B$1,العقود!$B$2:$B$501,0))),"غير موجود") -> غير موجود
A15: القيمة | B15: =IFERROR(IF(INDEX(العقود!$L$2:$L$501,MATCH($B$1,العقود!$B$2:$B$501,0))="","—",INDEX(العقود!$L$2:$L$501,MATCH($B$1,العقود!$B$2:$B$501,0))),"غير موجود") -> غير موجود
A16: العملة | B16: =IFERROR(IF(INDEX(العقود!$M$2:$M$501,MATCH($B$1,العقود!$B$2:$B$501,0))="","—",INDEX(العقود!$M$2:$M$501,MATCH($B$1,العقود!$B$2:$B$501,0))),"غير موجود") -> غير موجود
A17: الكميات | B17: =IFERROR(IF(INDEX(العقود!$N$2:$N$501,MATCH($B$1,العقود!$B$2:$B$501,0))="","—",INDEX(العقود!$N$2:$N$501,MATCH($B$1,العقود!$B$2:$B$501,0))),"غير موجود") -> غير موجود
A18: الإدارة المختصة | B18: =IFERROR(IF(INDEX(العقود!$O$2:$O$501,MATCH($B$1,العقود!$B$2:$B$501,0))="","—",INDEX(العقود!$O$2:$O$501,MATCH($B$1,العقود!$B$2:$B$501,0))),"غير موجود") -> غير موجود
A19: مسؤول المتابعة | B19: =IFERROR(IF(INDEX(العقود!$P$2:$P$501,MATCH($B$1,العقود!$B$2:$B$501,0))="","—",INDEX(العقود!$P$2:$P$501,MATCH($B$1,العقود!$B$2:$B$501,0))),"غير موجود") -> غير موجود
A20: ملف PDF | B20: =IFERROR(IF(INDEX(العقود!$V$2:$V$501,MATCH($B$1,العقود!$B$2:$B$501,0))="","—",INDEX(العقود!$V$2:$V$501,MATCH($B$1,العقود!$B$2:$B$501,0))),"غير موجود") -> غير موجود
A21: ملاحظات | B21: =IFERROR(IF(INDEX(العقود!$W$2:$W$501,MATCH($B$1,العقود!$B$2:$B$501,0))="","—",INDEX(العقود!$W$2:$W$501,MATCH($B$1,العقود!$B$2:$B$501,0))),"غير موجود") -> غير موجود
A22: آخر تمديد | B22: =IF(COUNTIF(التمديدات!$A$2:$A$301,$B$1)=0,"لا يوجد",_xlfn.MAXIFS(التمديدات!$B$2:$B$301,التمديدات!$A$2:$A$301,$B$1)) -> لا يوجد
A24: سجل التمديدات
A25: تاريخ القرار | B25: الانتهاء الجديد | C25: ملاحظة
A26: =IFERROR(INDEX(التمديدات!$B$1:$B$301,SMALL(التمديدات!$F$2:$F$301,1)),"") | B26: =IFERROR(INDEX(التمديدات!$C$1:$C$301,SMALL(التمديدات!$F$2:$F$301,1)),"") | C26: =IFERROR(INDEX(التمديدات!$D$1:$D$301,SMALL(التمديدات!$F$2:$F$301,1)),"")
A27: =IFERROR(INDEX(التمديدات!$B$1:$B$301,SMALL(التمديدات!$F$2:$F$301,2)),"") | B27: =IFERROR(INDEX(التمديدات!$C$1:$C$301,SMALL(التمديدات!$F$2:$F$301,2)),"") | C27: =IFERROR(INDEX(التمديدات!$D$1:$D$301,SMALL(التمديدات!$F$2:$F$301,2)),"")
A28: =IFERROR(INDEX(التمديدات!$B$1:$B$301,SMALL(التمديدات!$F$2:$F$301,3)),"") | B28: =IFERROR(INDEX(التمديدات!$C$1:$C$301,SMALL(التمديدات!$F$2:$F$301,3)),"") | C28: =IFERROR(INDEX(التمديدات!$D$1:$D$301,SMALL(التمديدات!$F$2:$F$301,3)),"")
A29: =IFERROR(INDEX(التمديدات!$B$1:$B$301,SMALL(التمديدات!$F$2:$F$301,4)),"") | B29: =IFERROR(INDEX(التمديدات!$C$1:$C$301,SMALL(التمديدات!$F$2:$F$301,4)),"") | C29: =IFERROR(INDEX(التمديدات!$D$1:$D$301,SMALL(التمديدات!$F$2:$F$301,4)),"")
A30: =IFERROR(INDEX(التمديدات!$B$1:$B$301,SMALL(التمديدات!$F$2:$F$301,5)),"") | B30: =IFERROR(INDEX(التمديدات!$C$1:$C$301,SMALL(التمديدات!$F$2:$F$301,5)),"") | C30: =IFERROR(INDEX(التمديدات!$D$1:$D$301,SMALL(التمديدات!$F$2:$F$301,5)),"")
A31: =IFERROR(INDEX(التمديدات!$B$1:$B$301,SMALL(التمديدات!$F$2:$F$301,6)),"") | B31: =IFERROR(INDEX(التمديدات!$C$1:$C$301,SMALL(التمديدات!$F$2:$F$301,6)),"") | C31: =IFERROR(INDEX(التمديدات!$D$1:$D$301,SMALL(التمديدات!$F$2:$F$301,6)),"")
A32: =IFERROR(INDEX(التمديدات!$B$1:$B$301,SMALL(التمديدات!$F$2:$F$301,7)),"") | B32: =IFERROR(INDEX(التمديدات!$C$1:$C$301,SMALL(التمديدات!$F$2:$F$301,7)),"") | C32: =IFERROR(INDEX(التمديدات!$D$1:$D$301,SMALL(التمديدات!$F$2:$F$301,7)),"")
A33: =IFERROR(INDEX(التمديدات!$B$1:$B$301,SMALL(التمديدات!$F$2:$F$301,8)),"") | B33: =IFERROR(INDEX(التمديدات!$C$1:$C$301,SMALL(التمديدات!$F$2:$F$301,8)),"") | C33: =IFERROR(INDEX(التمديدات!$D$1:$D$301,SMALL(التمديدات!$F$2:$F$301,8)),"")
A35: المراسلات
A36: رقم المراسلة | B36: التاريخ | C36: ملاحظة
A37: =IFERROR(INDEX(المراسلات!$B$1:$B$301,SMALL(المراسلات!$F$2:$F$301,1)),"") -> م/304 | B37: =IFERROR(INDEX(المراسلات!$C$1:$C$301,SMALL(المراسلات!$F$2:$F$301,1)),"") -> 46206 | C37: =IFERROR(INDEX(المراسلات!$D$1:$D$301,SMALL(المراسلات!$F$2:$F$301,1)),"") -> إخطار بقرب الانتهاء (مثال)
A38: =IFERROR(INDEX(المراسلات!$B$1:$B$301,SMALL(المراسلات!$F$2:$F$301,2)),"") | B38: =IFERROR(INDEX(المراسلات!$C$1:$C$301,SMALL(المراسلات!$F$2:$F$301,2)),"") | C38: =IFERROR(INDEX(المراسلات!$D$1:$D$301,SMALL(المراسلات!$F$2:$F$301,2)),"")
A39: =IFERROR(INDEX(المراسلات!$B$1:$B$301,SMALL(المراسلات!$F$2:$F$301,3)),"") | B39: =IFERROR(INDEX(المراسلات!$C$1:$C$301,SMALL(المراسلات!$F$2:$F$301,3)),"") | C39: =IFERROR(INDEX(المراسلات!$D$1:$D$301,SMALL(المراسلات!$F$2:$F$301,3)),"")
A40: =IFERROR(INDEX(المراسلات!$B$1:$B$301,SMALL(المراسلات!$F$2:$F$301,4)),"") | B40: =IFERROR(INDEX(المراسلات!$C$1:$C$301,SMALL(المراسلات!$F$2:$F$301,4)),"") | C40: =IFERROR(INDEX(المراسلات!$D$1:$D$301,SMALL(المراسلات!$F$2:$F$301,4)),"")
A41: =IFERROR(INDEX(المراسلات!$B$1:$B$301,SMALL(المراسلات!$F$2:$F$301,5)),"") | B41: =IFERROR(INDEX(المراسلات!$C$1:$C$301,SMALL(المراسلات!$F$2:$F$301,5)),"") | C41: =IFERROR(INDEX(المراسلات!$D$1:$D$301,SMALL(المراسلات!$F$2:$F$301,5)),"")
A42: =IFERROR(INDEX(المراسلات!$B$1:$B$301,SMALL(المراسلات!$F$2:$F$301,6)),"") | B42: =IFERROR(INDEX(المراسلات!$C$1:$C$301,SMALL(المراسلات!$F$2:$F$301,6)),"") | C42: =IFERROR(INDEX(المراسلات!$D$1:$D$301,SMALL(المراسلات!$F$2:$F$301,6)),"")
A43: =IFERROR(INDEX(المراسلات!$B$1:$B$301,SMALL(المراسلات!$F$2:$F$301,7)),"") | B43: =IFERROR(INDEX(المراسلات!$C$1:$C$301,SMALL(المراسلات!$F$2:$F$301,7)),"") | C43: =IFERROR(INDEX(المراسلات!$D$1:$D$301,SMALL(المراسلات!$F$2:$F$301,7)),"")
...

Sheet القوائم والإعدادات
A1: أنواع العقود | B1: الإدارات | D1: فترات التنبيه (أيام) | E1: القيمة | G1: حالة خاصة
A2: بيع وقود الديزل | B2: الإدارة التجارية | D2: تنبيه أول | E2: 90 | G2: معلق
A3: بيع البنزين | B3: إدارة المبيعات | D3: تنبيه ثانٍ | E3: 60 | G3: منتهٍ قبل موعده
A4: توريد منتجات نفطية | B4: الإدارة الفنية | D4: تنبيه عاجل | E4: 30
A5: تقديم خدمات | B5: الشؤون القانونية
A6: صيانة | D6: تُضاف أنواع/إدارات جديدة في الخانات الفارغة أسفل القوائم (حتى الصف 20).
A7: نقل وتشغيل

Sheet تعليمات
A1: طريقة الاستخدام
A2: 1) أضف الشركات في ورقة «الشركات» أولًا (الأزرق = خانات إدخال).
A3: 2) أضف العقد في أول صف فارغ بورقة «العقود» (الصيغ جاهزة حتى 500 عقد). الأعمدة الرمادية/السوداء تُحسب تلقائيًا ولا تُعدَّل.
A4: 3) التمديدات: سجّل كل تمديد كسطر جديد في ورقة «التمديدات» برقم العقد — لا يُحذف القديم، والانتهاء الفعلي يُحسب من آخر تمديد.
A5: 4) المراسلات: سجّلها في ورقة «المراسلات» برقم العقد.
A6: 5) البحث: استخدم الفلتر في رأس جدول «العقود» أو Ctrl+F. ولعرض ملف عقد كامل اكتب رقمه في «بطاقة العقد».
A7: 6) التنبيهات: ملوّنة في عمود الحالة والتنبيه، وتُضبط الفترات من «القوائم والإعدادات».
A8: 7) التقارير: صفِّ الجدول بالفلتر ثم اطبع أو احفظ PDF (ملف > طباعة).
A9: 8) النسخ الاحتياطي: انسخ الملف بتاريخ اليوم إلى قرص خارجي أو مجلد مؤمَّن (أسبوعيًا).
A10: 9) البيانات الحالية وهمية للتجربة — احذفها قبل إدخال البيانات الحقيقية. لا تحذف صفوف الصيغ؛ امسح خانات الإدخال فقط.
A11: ملاحظة: الصيغ تحتاج Excel 2019 أو أحدث (دالة MAXIFS).
